<?xml version="1.0"?>
<robot xmlns:xacro="http://www.ros.org/wiki/xacro" name="gripperRL" >

    <!-- Linear Actuator -->
    <link name="base_link">
        <inertial>
            <mass value="1.0"/>
            <origin xyz="0 0 0"/>
            <inertia ixx="0.01" iyy="0.01" izz="0.01" ixy="0.0" ixz="0.0" iyz="0.0"/>
        </inertial>
        <visual>
            <geometry>
                <box size="0.1 0.1 0.1"/>
            </geometry>
            <material name="gray"/>
        </visual>
        <collision>
            <geometry>
                <box size="0.1 0.1 0.1"/>
            </geometry>
        </collision>
    </link>

    <link name="linear_actuator">
        <inertial>
            <mass value="0.5"/>
            <origin xyz="0 0 0"/>
            <inertia ixx="0.002" iyy="0.002" izz="0.002" ixy="0.0" ixz="0.0" iyz="0.0"/>
        </inertial>
        <visual>
            <geometry>
                <cylinder radius="0.05" length="0.2"/>
            </geometry>
            <material name="blue"/>
        </visual>
        <collision>
            <geometry>
                <cylinder radius="0.05" length="0.2"/>
            </geometry>
        </collision>
    </link>

    <joint name="linear_joint" type="prismatic">
        <parent link="base_link"/>
        <child link="linear_actuator"/>
        <origin xyz="0 0 0.1" rpy="0 0 0"/>
        <axis xyz="0 0 1"/>
        <limit lower="0" upper="0.1" effort="100" velocity="0.1"/>
    </joint>

    <!-- Rotational Actuator -->
    <link name="rotational_actuator">
        <inertial>
            <mass value="0.3"/>
            <origin xyz="0 0 0"/>
            <inertia ixx="0.001" iyy="0.001" izz="0.001" ixy="0.0" ixz="0.0" iyz="0.0"/>
        </inertial>
        <visual>
            <geometry>
                <cylinder radius="0.05" length="0.1"/>
            </geometry>
            <material name="red"/>
        </visual>
        <collision>
            <geometry>
                <cylinder radius="0.05" length="0.1"/>
            </geometry>
        </collision>
    </link>

    <joint name="rotational_joint" type="revolute">
        <parent link="linear_actuator"/>
        <child link="rotational_actuator"/>
        <origin xyz="0 0 0.2" rpy="0 0 0"/>
        <axis xyz="0 1 0"/>
        <limit lower="-1.57" upper="1.57" effort="100" velocity="1.0"/>
    </joint>

</robot>
