<?xml version="1.0"?>
<!-- Basic differential drive mobile base -->
<robot xmlns:xacro="http://www.ros.org/wiki/xacro" name="gripper_robot">
    <xacro:arg name="prefix" default="" />

    <!-- Include the diffbot_description.urdf.xacro -->
    <xacro:include
        filename="$(find bots_description)/ackerman/urdf/ackerman.urdf.xacro" />
    <!-- Import Rviz colors -->
    <xacro:include
        filename="$(find bots_description)/common/urdf/materials.xacro" />

    <link name="motor"/>
    <link name="steering"/>
    <joint name="motor_joint" type="revolute">
        <origin xyz="0 0 0" rpy="0 0 0"/>
        <parent link="base_link"/>
        <child link="motor"/>
        <axis xyz="0 0 1"/>
        <limit lower="-3.14159" upper="3.14159" effort="100" velocity="1"/>
    
    </joint>
    <joint name="steering_joint" type="revolute">
        <origin xyz="0 0 0" rpy="0 0 0"/>
        <parent link="base_link"/>
        <child link="steering"/>
        <axis xyz="0 0 1"/>
        <limit lower="-3.14159" upper="3.14159" effort="100" velocity="1"/>
    </joint>

  <!-- Tu definición de robot -->
  
  <!-- Etiqueta ros2_control -->
  <ros2_control name="AckermannHardware" type="system">
    <hardware>
      <plugin>yb_eb/YbEbHw</plugin>
      <!-- <param name="motor_name">motor_joint</param>
      <param name="steering_name">steering_joint</param>
      <param name="debug">false</param>
      <param name="max_ang_motor">100</param>
      <param name="min_ang_motor">86</param>
      <param name="max_ang_steering">115</param>
      <param name="min_ang_steering">65</param> -->

        <param name = "motor_name">motor_joint</param>
        <param name = "steering_name">steering_joint</param>
        <param name = "debug">false</param>
        <param name = "max_forward_motor"> 98.0</param>
        <param name = "min_forward_motor"> 91.0</param>
        <param name = "max_reverse_motor"> 89.0</param>
        <param name = "min_reverse_motor"> 76.0</param>
        <param name = "max_ang_steering"> 115.0</param>
        <param name = "min_ang_steering"> 65.0</param>
        <param name = "create_receive_threading">false</param>

        
    </hardware>
       
        <joint name="steering_joint">
          <!-- Command interface to control velocity -->
          <command_interface name="position">
              <!-- <param name="min">-1</param>
              <param name="max">1</param> -->
          </command_interface>
          <!-- State interfaces to read position and velocity -->
          <state_interface name="position" >
                <!-- <param name="initial_value">0</param> -->
            </state_interface>
          <state_interface name="velocity" >
                <!-- <param name="initial_value">0</param> -->
            </state_interface>
      </joint>

       <joint name="motor_joint">
          <!-- Command interface to control velocity -->
          <command_interface name="velocity">
              <!-- <param name="min">-1</param>
              <param name="max">1</param> -->
          </command_interface>
          <!-- State interfaces to read position and velocity -->
          <state_interface name="position" >
                <!-- <param name="initial_value">0</param> -->
            </state_interface>
          <state_interface name="velocity" >
                <!-- <param name="initial_value">0</param> -->
            </state_interface>
        </joint>
  </ros2_control>


    <!-- Otras definiciones de links y joints -->

</robot>